Epoch: 1/100
Traceback (most recent call last):
  File "main.py", line 104, in <module>
    run(cfg)
  File "main.py", line 87, in run
    device       = device)
  File "/home/inho/df_detection/experiments_xception/train.py", line 133, in fit
    train_metrics = train(model, trainloader, criterion, optimizer, log_interval, device)
  File "/home/inho/df_detection/experiments_xception/train.py", line 46, in train
    outputs = model(inputs)
  File "/home/inho/anaconda3/envs/df_detection/lib/python3.7/site-packages/torch/nn/modules/module.py", line 1130, in _call_impl
    return forward_call(*input, **kwargs)
  File "/home/inho/anaconda3/envs/df_detection/lib/python3.7/site-packages/timm/models/xception.py", line 219, in forward
    x = self.forward_features(x)
  File "/home/inho/anaconda3/envs/df_detection/lib/python3.7/site-packages/timm/models/xception.py", line 183, in forward_features
    x = self.bn1(x)
  File "/home/inho/anaconda3/envs/df_detection/lib/python3.7/site-packages/torch/nn/modules/module.py", line 1130, in _call_impl
    return forward_call(*input, **kwargs)
  File "/home/inho/anaconda3/envs/df_detection/lib/python3.7/site-packages/torch/nn/modules/batchnorm.py", line 148, in forward
    self.num_batches_tracked.add_(1)  # type: ignore[has-type]
RuntimeError: CUDA error: no kernel image is available for execution on the device
CUDA kernel errors might be asynchronously reported at some other API call,so the stacktrace below might be incorrect.
For debugging consider passing CUDA_LAUNCH_BLOCKING=1.